[2023-01-05T12:44:30.003+0000] {taskinstance.py:1087} INFO - Dependencies all met for <TaskInstance: uk_accidents_etl_pipeline.create_dashboard manual__2023-01-05T12:17:22.287490+00:00 [queued]>
[2023-01-05T12:44:30.048+0000] {taskinstance.py:1087} INFO - Dependencies all met for <TaskInstance: uk_accidents_etl_pipeline.create_dashboard manual__2023-01-05T12:17:22.287490+00:00 [queued]>
[2023-01-05T12:44:30.049+0000] {taskinstance.py:1283} INFO - 
--------------------------------------------------------------------------------
[2023-01-05T12:44:30.050+0000] {taskinstance.py:1284} INFO - Starting attempt 6 of 7
[2023-01-05T12:44:30.050+0000] {taskinstance.py:1285} INFO - 
--------------------------------------------------------------------------------
[2023-01-05T12:44:30.118+0000] {taskinstance.py:1304} INFO - Executing <Task(PythonOperator): create_dashboard> on 2023-01-05 12:17:22.287490+00:00
[2023-01-05T12:44:30.126+0000] {standard_task_runner.py:55} INFO - Started process 1779 to run task
[2023-01-05T12:44:30.134+0000] {standard_task_runner.py:82} INFO - Running: ['***', 'tasks', 'run', 'uk_accidents_etl_pipeline', 'create_dashboard', 'manual__2023-01-05T12:17:22.287490+00:00', '--job-id', '40', '--raw', '--subdir', 'DAGS_FOLDER/milestone_3.py', '--cfg-path', '/tmp/tmpqrscze8h']
[2023-01-05T12:44:30.138+0000] {standard_task_runner.py:83} INFO - Job 40: Subtask create_dashboard
[2023-01-05T12:44:30.282+0000] {task_command.py:389} INFO - Running <TaskInstance: uk_accidents_etl_pipeline.create_dashboard manual__2023-01-05T12:17:22.287490+00:00 [running]> on host ecc1437a0be2
[2023-01-05T12:44:30.519+0000] {taskinstance.py:1513} INFO - Exporting the following env vars:
AIRFLOW_CTX_DAG_OWNER=***
AIRFLOW_CTX_DAG_ID=uk_accidents_etl_pipeline
AIRFLOW_CTX_TASK_ID=create_dashboard
AIRFLOW_CTX_EXECUTION_DATE=2023-01-05T12:17:22.287490+00:00
AIRFLOW_CTX_TRY_NUMBER=6
AIRFLOW_CTX_DAG_RUN_ID=manual__2023-01-05T12:17:22.287490+00:00
[2023-01-05T12:44:30.536+0000] {taskinstance.py:1772} ERROR - Task failed with exception
Traceback (most recent call last):
  File "/home/airflow/.local/lib/python3.7/site-packages/airflow/operators/python.py", line 175, in execute
    return_value = self.execute_callable()
  File "/home/airflow/.local/lib/python3.7/site-packages/airflow/operators/python.py", line 192, in execute_callable
    return self.python_callable(*self.op_args, **self.op_kwargs)
  File "/opt/airflow/dags/dashbord.py", line 31, in create_dashboard
    df1 = pd.read_csv(filename2)
  File "/home/airflow/.local/lib/python3.7/site-packages/pandas/util/_decorators.py", line 311, in wrapper
    return func(*args, **kwargs)
  File "/home/airflow/.local/lib/python3.7/site-packages/pandas/io/parsers/readers.py", line 586, in read_csv
    return _read(filepath_or_buffer, kwds)
  File "/home/airflow/.local/lib/python3.7/site-packages/pandas/io/parsers/readers.py", line 482, in _read
    parser = TextFileReader(filepath_or_buffer, **kwds)
  File "/home/airflow/.local/lib/python3.7/site-packages/pandas/io/parsers/readers.py", line 811, in __init__
    self._engine = self._make_engine(self.engine)
  File "/home/airflow/.local/lib/python3.7/site-packages/pandas/io/parsers/readers.py", line 1040, in _make_engine
    return mapping[engine](self.f, **self.options)  # type: ignore[call-arg]
  File "/home/airflow/.local/lib/python3.7/site-packages/pandas/io/parsers/c_parser_wrapper.py", line 69, in __init__
    self._reader = parsers.TextReader(self.handles.handle, **kwds)
  File "pandas/_libs/parsers.pyx", line 542, in pandas._libs.parsers.TextReader.__cinit__
  File "pandas/_libs/parsers.pyx", line 642, in pandas._libs.parsers.TextReader._get_header
  File "pandas/_libs/parsers.pyx", line 843, in pandas._libs.parsers.TextReader._tokenize_rows
  File "pandas/_libs/parsers.pyx", line 1917, in pandas._libs.parsers.raise_parser_error
UnicodeDecodeError: 'utf-8' codec can't decode byte 0x90 in position 7: invalid start byte
[2023-01-05T12:44:30.595+0000] {taskinstance.py:1327} INFO - Marking task as UP_FOR_RETRY. dag_id=uk_accidents_etl_pipeline, task_id=create_dashboard, execution_date=20230105T121722, start_date=20230105T124430, end_date=20230105T124430
[2023-01-05T12:44:30.681+0000] {standard_task_runner.py:105} ERROR - Failed to execute job 40 for task create_dashboard ('utf-8' codec can't decode byte 0x90 in position 7: invalid start byte; 1779)
[2023-01-05T12:44:30.746+0000] {local_task_job.py:159} INFO - Task exited with return code 1
[2023-01-05T12:44:30.842+0000] {taskinstance.py:2582} INFO - 0 downstream tasks scheduled from follow-on schedule check
