[2023-01-05T17:05:26.281+0000] {taskinstance.py:1087} INFO - Dependencies all met for <TaskInstance: uk_accidents_etl_pipeline.create_dashboard manual__2023-01-05T12:17:22.287490+00:00 [queued]>
[2023-01-05T17:05:26.301+0000] {taskinstance.py:1087} INFO - Dependencies all met for <TaskInstance: uk_accidents_etl_pipeline.create_dashboard manual__2023-01-05T12:17:22.287490+00:00 [queued]>
[2023-01-05T17:05:26.301+0000] {taskinstance.py:1283} INFO - 
--------------------------------------------------------------------------------
[2023-01-05T17:05:26.302+0000] {taskinstance.py:1284} INFO - Starting attempt 8 of 8
[2023-01-05T17:05:26.303+0000] {taskinstance.py:1285} INFO - 
--------------------------------------------------------------------------------
[2023-01-05T17:05:26.346+0000] {taskinstance.py:1304} INFO - Executing <Task(PythonOperator): create_dashboard> on 2023-01-05 12:17:22.287490+00:00
[2023-01-05T17:05:26.424+0000] {standard_task_runner.py:82} INFO - Running: ['***', 'tasks', 'run', 'uk_accidents_etl_pipeline', 'create_dashboard', 'manual__2023-01-05T12:17:22.287490+00:00', '--job-id', '43', '--raw', '--subdir', 'DAGS_FOLDER/milestone_3.py', '--cfg-path', '/tmp/tmplo70wvyy']
[2023-01-05T17:05:26.431+0000] {standard_task_runner.py:83} INFO - Job 43: Subtask create_dashboard
[2023-01-05T17:05:26.422+0000] {standard_task_runner.py:55} INFO - Started process 237 to run task
[2023-01-05T17:05:26.578+0000] {task_command.py:389} INFO - Running <TaskInstance: uk_accidents_etl_pipeline.create_dashboard manual__2023-01-05T12:17:22.287490+00:00 [running]> on host ecc1437a0be2
[2023-01-05T17:05:26.905+0000] {taskinstance.py:1513} INFO - Exporting the following env vars:
AIRFLOW_CTX_DAG_OWNER=***
AIRFLOW_CTX_DAG_ID=uk_accidents_etl_pipeline
AIRFLOW_CTX_TASK_ID=create_dashboard
AIRFLOW_CTX_EXECUTION_DATE=2023-01-05T12:17:22.287490+00:00
AIRFLOW_CTX_TRY_NUMBER=8
AIRFLOW_CTX_DAG_RUN_ID=manual__2023-01-05T12:17:22.287490+00:00
[2023-01-05T17:05:30.516+0000] {taskinstance.py:1772} ERROR - Task failed with exception
Traceback (most recent call last):
  File "/home/airflow/.local/lib/python3.7/site-packages/airflow/operators/python.py", line 175, in execute
    return_value = self.execute_callable()
  File "/home/airflow/.local/lib/python3.7/site-packages/airflow/operators/python.py", line 192, in execute_callable
    return self.python_callable(*self.op_args, **self.op_kwargs)
  File "/opt/airflow/dags/dashbord.py", line 36, in create_dashboard
    df2 = pd.read_csv(filename1)
  File "/home/airflow/.local/lib/python3.7/site-packages/pandas/util/_decorators.py", line 311, in wrapper
    return func(*args, **kwargs)
  File "/home/airflow/.local/lib/python3.7/site-packages/pandas/io/parsers/readers.py", line 586, in read_csv
    return _read(filepath_or_buffer, kwds)
  File "/home/airflow/.local/lib/python3.7/site-packages/pandas/io/parsers/readers.py", line 482, in _read
    parser = TextFileReader(filepath_or_buffer, **kwds)
  File "/home/airflow/.local/lib/python3.7/site-packages/pandas/io/parsers/readers.py", line 811, in __init__
    self._engine = self._make_engine(self.engine)
  File "/home/airflow/.local/lib/python3.7/site-packages/pandas/io/parsers/readers.py", line 1040, in _make_engine
    return mapping[engine](self.f, **self.options)  # type: ignore[call-arg]
  File "/home/airflow/.local/lib/python3.7/site-packages/pandas/io/parsers/c_parser_wrapper.py", line 51, in __init__
    self._open_handles(src, kwds)
  File "/home/airflow/.local/lib/python3.7/site-packages/pandas/io/parsers/base_parser.py", line 229, in _open_handles
    errors=kwds.get("encoding_errors", "strict"),
  File "/home/airflow/.local/lib/python3.7/site-packages/pandas/io/common.py", line 707, in get_handle
    newline="",
FileNotFoundError: [Errno 2] No such file or directory: '/opt/airflow/data/accident_cleaned_stage0.csv'
[2023-01-05T17:05:30.648+0000] {taskinstance.py:1327} INFO - Marking task as FAILED. dag_id=uk_accidents_etl_pipeline, task_id=create_dashboard, execution_date=20230105T121722, start_date=20230105T170526, end_date=20230105T170530
[2023-01-05T17:05:30.744+0000] {standard_task_runner.py:105} ERROR - Failed to execute job 43 for task create_dashboard ([Errno 2] No such file or directory: '/opt/airflow/data/accident_cleaned_stage0.csv'; 237)
[2023-01-05T17:05:30.802+0000] {local_task_job.py:159} INFO - Task exited with return code 1
[2023-01-05T17:05:30.871+0000] {taskinstance.py:2582} INFO - 0 downstream tasks scheduled from follow-on schedule check
