[2023-01-02T23:33:22.687+0000] {taskinstance.py:1087} INFO - Dependencies all met for <TaskInstance: uk_accidents_etl_pipeline.load_to_postgres manual__2023-01-02T18:29:32.736333+00:00 [queued]>
[2023-01-02T23:33:22.764+0000] {taskinstance.py:1087} INFO - Dependencies all met for <TaskInstance: uk_accidents_etl_pipeline.load_to_postgres manual__2023-01-02T18:29:32.736333+00:00 [queued]>
[2023-01-02T23:33:22.777+0000] {taskinstance.py:1283} INFO - 
--------------------------------------------------------------------------------
[2023-01-02T23:33:22.779+0000] {taskinstance.py:1284} INFO - Starting attempt 3 of 3
[2023-01-02T23:33:22.780+0000] {taskinstance.py:1285} INFO - 
--------------------------------------------------------------------------------
[2023-01-02T23:33:22.898+0000] {taskinstance.py:1304} INFO - Executing <Task(PythonOperator): load_to_postgres> on 2023-01-02 18:29:32.736333+00:00
[2023-01-02T23:33:22.951+0000] {standard_task_runner.py:55} INFO - Started process 218 to run task
[2023-01-02T23:33:22.976+0000] {standard_task_runner.py:82} INFO - Running: ['***', 'tasks', 'run', 'uk_accidents_etl_pipeline', 'load_to_postgres', 'manual__2023-01-02T18:29:32.736333+00:00', '--job-id', '11', '--raw', '--subdir', 'DAGS_FOLDER/milestone_3.py', '--cfg-path', '/tmp/tmpesgjd91q']
[2023-01-02T23:33:23.008+0000] {standard_task_runner.py:83} INFO - Job 11: Subtask load_to_postgres
[2023-01-02T23:33:23.382+0000] {task_command.py:389} INFO - Running <TaskInstance: uk_accidents_etl_pipeline.load_to_postgres manual__2023-01-02T18:29:32.736333+00:00 [running]> on host 82068c2abeb3
[2023-01-02T23:33:23.855+0000] {taskinstance.py:1513} INFO - Exporting the following env vars:
AIRFLOW_CTX_DAG_OWNER=***
AIRFLOW_CTX_DAG_ID=uk_accidents_etl_pipeline
AIRFLOW_CTX_TASK_ID=load_to_postgres
AIRFLOW_CTX_EXECUTION_DATE=2023-01-02T18:29:32.736333+00:00
AIRFLOW_CTX_TRY_NUMBER=3
AIRFLOW_CTX_DAG_RUN_ID=manual__2023-01-02T18:29:32.736333+00:00
[2023-01-02T23:33:23.870+0000] {taskinstance.py:1772} ERROR - Task failed with exception
Traceback (most recent call last):
  File "/home/airflow/.local/lib/python3.7/site-packages/airflow/operators/python.py", line 175, in execute
    return_value = self.execute_callable()
  File "/home/airflow/.local/lib/python3.7/site-packages/airflow/operators/python.py", line 192, in execute_callable
    return self.python_callable(*self.op_args, **self.op_kwargs)
  File "/opt/airflow/dags/milestone_3.py", line 16, in load_to_postgres
    df = pd.read_csv(filename1)
  File "/home/airflow/.local/lib/python3.7/site-packages/pandas/util/_decorators.py", line 311, in wrapper
    return func(*args, **kwargs)
  File "/home/airflow/.local/lib/python3.7/site-packages/pandas/io/parsers/readers.py", line 586, in read_csv
    return _read(filepath_or_buffer, kwds)
  File "/home/airflow/.local/lib/python3.7/site-packages/pandas/io/parsers/readers.py", line 482, in _read
    parser = TextFileReader(filepath_or_buffer, **kwds)
  File "/home/airflow/.local/lib/python3.7/site-packages/pandas/io/parsers/readers.py", line 811, in __init__
    self._engine = self._make_engine(self.engine)
  File "/home/airflow/.local/lib/python3.7/site-packages/pandas/io/parsers/readers.py", line 1040, in _make_engine
    return mapping[engine](self.f, **self.options)  # type: ignore[call-arg]
  File "/home/airflow/.local/lib/python3.7/site-packages/pandas/io/parsers/c_parser_wrapper.py", line 51, in __init__
    self._open_handles(src, kwds)
  File "/home/airflow/.local/lib/python3.7/site-packages/pandas/io/parsers/base_parser.py", line 229, in _open_handles
    errors=kwds.get("encoding_errors", "strict"),
  File "/home/airflow/.local/lib/python3.7/site-packages/pandas/io/common.py", line 707, in get_handle
    newline="",
FileNotFoundError: [Errno 2] No such file or directory: '/opt/airflow/data/accident_cleaned_stage2.csv'
[2023-01-02T23:33:23.928+0000] {taskinstance.py:1327} INFO - Marking task as FAILED. dag_id=uk_accidents_etl_pipeline, task_id=load_to_postgres, execution_date=20230102T182932, start_date=20230102T233322, end_date=20230102T233323
[2023-01-02T23:33:24.072+0000] {standard_task_runner.py:105} ERROR - Failed to execute job 11 for task load_to_postgres ([Errno 2] No such file or directory: '/opt/airflow/data/accident_cleaned_stage2.csv'; 218)
[2023-01-02T23:33:24.114+0000] {local_task_job.py:159} INFO - Task exited with return code 1
[2023-01-02T23:33:24.243+0000] {taskinstance.py:2582} INFO - 0 downstream tasks scheduled from follow-on schedule check
