[2023-01-02T23:53:28.589+0000] {taskinstance.py:1087} INFO - Dependencies all met for <TaskInstance: uk_accidents_etl_pipeline.milestone_1 manual__2023-01-02T23:53:19.341738+00:00 [queued]>
[2023-01-02T23:53:28.661+0000] {taskinstance.py:1087} INFO - Dependencies all met for <TaskInstance: uk_accidents_etl_pipeline.milestone_1 manual__2023-01-02T23:53:19.341738+00:00 [queued]>
[2023-01-02T23:53:28.669+0000] {taskinstance.py:1283} INFO - 
--------------------------------------------------------------------------------
[2023-01-02T23:53:28.676+0000] {taskinstance.py:1284} INFO - Starting attempt 1 of 2
[2023-01-02T23:53:28.677+0000] {taskinstance.py:1285} INFO - 
--------------------------------------------------------------------------------
[2023-01-02T23:53:28.780+0000] {taskinstance.py:1304} INFO - Executing <Task(PythonOperator): milestone_1> on 2023-01-02 23:53:19.341738+00:00
[2023-01-02T23:53:28.792+0000] {standard_task_runner.py:55} INFO - Started process 1248 to run task
[2023-01-02T23:53:28.807+0000] {standard_task_runner.py:82} INFO - Running: ['***', 'tasks', 'run', 'uk_accidents_etl_pipeline', 'milestone_1', 'manual__2023-01-02T23:53:19.341738+00:00', '--job-id', '16', '--raw', '--subdir', 'DAGS_FOLDER/milestone_3.py', '--cfg-path', '/tmp/tmpsfl1y0o0']
[2023-01-02T23:53:28.820+0000] {standard_task_runner.py:83} INFO - Job 16: Subtask milestone_1
[2023-01-02T23:53:29.319+0000] {task_command.py:389} INFO - Running <TaskInstance: uk_accidents_etl_pipeline.milestone_1 manual__2023-01-02T23:53:19.341738+00:00 [running]> on host 82068c2abeb3
[2023-01-02T23:53:29.695+0000] {taskinstance.py:1513} INFO - Exporting the following env vars:
AIRFLOW_CTX_DAG_OWNER=***
AIRFLOW_CTX_DAG_ID=uk_accidents_etl_pipeline
AIRFLOW_CTX_TASK_ID=milestone_1
AIRFLOW_CTX_EXECUTION_DATE=2023-01-02T23:53:19.341738+00:00
AIRFLOW_CTX_TRY_NUMBER=1
AIRFLOW_CTX_DAG_RUN_ID=manual__2023-01-02T23:53:19.341738+00:00
[2023-01-02T23:54:09.841+0000] {local_task_job.py:224} WARNING - State of this instance has been externally set to restarting. Terminating instance.
[2023-01-02T23:54:09.850+0000] {process_utils.py:133} INFO - Sending Signals.SIGTERM to group 1248. PIDs of all processes in the group: [1248]
[2023-01-02T23:54:09.852+0000] {process_utils.py:84} INFO - Sending the signal Signals.SIGTERM to group 1248
[2023-01-02T23:54:09.853+0000] {taskinstance.py:1483} ERROR - Received SIGTERM. Terminating subprocesses.
[2023-01-02T23:54:09.888+0000] {taskinstance.py:1772} ERROR - Task failed with exception
Traceback (most recent call last):
  File "/home/airflow/.local/lib/python3.7/site-packages/airflow/operators/python.py", line 175, in execute
    return_value = self.execute_callable()
  File "/home/airflow/.local/lib/python3.7/site-packages/airflow/operators/python.py", line 192, in execute_callable
    return self.python_callable(*self.op_args, **self.op_kwargs)
  File "/opt/airflow/dags/milestone_1.py", line 474, in clean_and_transform
    process_5.to_csv('/opt/airflow/data/accident_cleaned_stage1.csv')
  File "/home/airflow/.local/lib/python3.7/site-packages/pandas/core/generic.py", line 3482, in to_csv
    storage_options=storage_options,
  File "/home/airflow/.local/lib/python3.7/site-packages/pandas/io/formats/format.py", line 1105, in to_csv
    csv_formatter.save()
  File "/home/airflow/.local/lib/python3.7/site-packages/pandas/io/formats/csvs.py", line 257, in save
    self._save()
  File "/home/airflow/.local/lib/python3.7/site-packages/pandas/io/formats/csvs.py", line 262, in _save
    self._save_body()
  File "/home/airflow/.local/lib/python3.7/site-packages/pandas/io/formats/csvs.py", line 300, in _save_body
    self._save_chunk(start_i, end_i)
  File "/home/airflow/.local/lib/python3.7/site-packages/pandas/io/formats/csvs.py", line 316, in _save_chunk
    self.writer,
  File "pandas/_libs/writers.pyx", line 55, in pandas._libs.writers.write_csv_rows
  File "/home/airflow/.local/lib/python3.7/site-packages/airflow/models/taskinstance.py", line 1485, in signal_handler
    raise AirflowException("Task received SIGTERM signal")
airflow.exceptions.AirflowException: Task received SIGTERM signal
[2023-01-02T23:54:09.912+0000] {taskinstance.py:1327} INFO - Marking task as UP_FOR_RETRY. dag_id=uk_accidents_etl_pipeline, task_id=milestone_1, execution_date=20230102T235319, start_date=20230102T235328, end_date=20230102T235409
[2023-01-02T23:54:09.989+0000] {standard_task_runner.py:105} ERROR - Failed to execute job 16 for task milestone_1 (Task received SIGTERM signal; 1248)
[2023-01-02T23:54:10.147+0000] {process_utils.py:79} INFO - Process psutil.Process(pid=1248, status='terminated', exitcode=1, started='23:53:28') (1248) terminated with exit code 1
